Workbook

Sheet cleaned_orders
A1: order_id | B1: order_date | C1: ship_date | D1: order_date_status | E1: ship_date_status | F1: shipping_delay_days | G1: ship_before_order_flag | H1: customer_id | I1: customer_name | J1: segment | K1: region | L1: region_filled_flag | M1: state | N1: city | O1: category | P1: sub_category | Q1: product_name | R1: ship_mode | S1: ship_mode_filled_flag | T1: quantity | U1: unit_price | V1: discount_raw | W1: cleaned_discount | X1: discount_issue_flag | Y1: sales_raw | Z1: cost | AA1: profit_raw | AB1: payment_status | AC1: order_status | AD1: calculated_sales | AE1: calculated_profit | AF1: profit_margin | AG1: sales_mismatch_flag | AH1: profit_mismatch_flag | AI1: order_month | AJ1: order_year | AK1: duplicate_status | AL1: refund_flag | AM1: excluded_from_sales_summary | AN1: data_quality_flag
A2: =raw_data!A2 -> ORD-2024-10001 | B2: =IFERROR(IF(MID(raw_data!B2,3,1)="/",DATE(VALUE(RIGHT(raw_data!B2,4)),VALUE(LEFT(raw_data!B2,2)),VALUE(MID(raw_data!B2,4,2))),IF(MID(raw_data!B2,3,1)="-",DATE(VALUE(RIGHT(raw_data!B2,4)),VALUE(MID(raw_data!B2,4,2)),VALUE(LEFT(raw_data!B2,2))),IF(MID(raw_data!B2,5,1)="-",DATE(VALUE(LEFT(raw_data!B2,4)),VALUE(MID(raw_data!B2,6,2)),VALUE(RIGHT(raw_data!B2,2))),DATE(VALUE(RIGHT(raw_data!B2,4)),MATCH(MID(raw_data!B2,4,3),{"Jan","Feb","Mar","Apr","May","Jun","Jul","Aug","Sep","Oct","Nov","Dec"},0),VALUE(LEFT(raw_data!B2,2)))))),"") -> 45494 | C2: =IFERROR(IF(MID(raw_data!C2,3,1)="/",DATE(VALUE(RIGHT(raw_data!C2,4)),VALUE(LEFT(raw_data!C2,2)),VALUE(MID(raw_data!C2,4,2))),IF(MID(raw_data!C2,3,1)="-",DATE(VALUE(RIGHT(raw_data!C2,4)),VALUE(MID(raw_data!C2,4,2)),VALUE(LEFT(raw_data!C2,2))),IF(MID(raw_data!C2,5,1)="-",DATE(VALUE(LEFT(raw_data!C2,4)),VALUE(MID(raw_data!C2,6,2)),VALUE(RIGHT(raw_data!C2,2))),DATE(VALUE(RIGHT(raw_data!C2,4)),MATCH(MID(raw_data!C2,4,3),{"Jan","Feb","Mar","Apr","May","Jun","Jul","Aug","Sep","Oct","Nov","Dec"},0),VALUE(LEFT(raw_data!C2,2)))))),"") -> 45500 | D2: =IF(TRIM(raw_data!B2)="","Missing",IF(B2="","Invalid/Unrecognized","Valid")) -> Valid | E2: =IF(TRIM(raw_data!C2)="","Missing",IF(C2="","Invalid/Unrecognized","Valid")) -> Valid | F2: =IF(OR(B2="",C2=""),"",C2-B2) -> 6 | G2: =IF(F2="","N/A",IF(F2<0,"Invalid - Ship Before Order","OK")) -> OK | H2: =raw_data!D2 -> CUST-4655 | I2: =PROPER(TRIM(raw_data!E2)) -> Karan Malhotra | J2: =PROPER(TRIM(raw_data!F2)) -> Consumer | K2: =IF(TRIM(raw_data!G2)="","Unknown",PROPER(TRIM(raw_data!G2))) -> North | L2: =IF(TRIM(raw_data!G2)="","Filled - Unknown","OK") -> OK | M2: =PROPER(TRIM(raw_data!H2)) -> Rajasthan | N2: =PROPER(TRIM(raw_data!I2)) -> Jaipur | O2: =PROPER(TRIM(raw_data!J2)) -> Office Supplies | P2: =PROPER(TRIM(raw_data!K2)) -> Paper | Q2: =TRIM(raw_data!L2) -> Pro Paper 122 | R2: =IF(TRIM(raw_data!M2)="","Unknown",PROPER(TRIM(raw_data!M2))) -> Second Class | S2: =IF(TRIM(raw_data!M2)="","Filled - Unknown","OK") -> OK | T2: =raw_data!N2 -> 8 | U2: =raw_data!O2 -> 2976.45 | V2: =raw_data!P2 -> 0.2 | W2: =IF(raw_data!P2="",0,IF(ISTEXT(raw_data!P2),IF(RIGHT(raw_data!P2,1)="%",VALUE(LEFT(raw_data!P2,LEN(raw_data!P2)-1))/100,VALUE(raw_data!P2)),raw_data!P2)) -> 0.2 | X2: =IF(raw_data!P2="","Missing - Defaulted to 0",IF(W2<0,"Negative - Invalid",IF(W2>0.3,"Above Allowed Range - Invalid","Valid"))) -> Valid | Y2: =raw_data!Q2 -> 19049.28 | Z2: =raw_data!R2 -> 15841.89 | AA2: =raw_data!S2 -> 3207.39 | AB2: =PROPER(TRIM(raw_data!T2)) -> Paid | AC2: =PROPER(TRIM(raw_data!U2)) -> Completed | AD2: =T2*U2*(1-W2) -> 19049.28 | AE2: =AD2-Z2 -> 3207.39 | AF2: =IF(AD2=0,0,AE2/AD2) -> 0.16837329 | AG2: =IF(ABS(Y2-AD2)>1,"Mismatch","OK") -> OK | AH2: =IF(ABS(AA2-AE2)>1,"Mismatch","OK") -> OK | AI2: =IF(B2="","",MONTH(B2)) -> 7 | AJ2: =IF(B2="","",YEAR(B2)) -> 2024 | AK2: =IF(COUNTIF(raw_data!$A$2:$A$913,A2)>1,"Conflicting Duplicate - Flagged for Review","Unique") -> Unique | AL2: =IF(AB2="Refunded","Yes","No") -> No | AM2: =IF(OR(AC2<>"Completed",AB2="Failed"),"Excluded","Included") -> Included | AN2: =IF(OR(D2="Invalid/Unrecognized",E2="Invalid/Unrecognized",G2="Invalid - Ship Before Order",X2="Negative - Invalid",X2="Above Allowed Range - Invalid",AG2="Mismatch",AH2="Mismatch",AK2="Conflicting Duplicate - Flagged for Review"),"Invalid",IF(OR(L2="Filled - Unknown",S2="Filled - Unknown",X2="Missing - Defaulted to 0",AL2="Yes",AC2="Cancelled",AC2="Returned"),"Warning","Clean")) -> Clean
A3: =raw_data!A3 -> ORD-2024-10002 | B3: =IFERROR(IF(MID(raw_data!B3,3,1)="/",DATE(VALUE(RIGHT(raw_data!B3,4)),VALUE(LEFT(raw_data!B3,2)),VALUE(MID(raw_data!B3,4,2))),IF(MID(raw_data!B3,3,1)="-",DATE(VALUE(RIGHT(raw_data!B3,4)),VALUE(MID(raw_data!B3,4,2)),VALUE(LEFT(raw_data!B3,2))),IF(MID(raw_data!B3,5,1)="-",DATE(VALUE(LEFT(raw_data!B3,4)),VALUE(MID(raw_data!B3,6,2)),VALUE(RIGHT(raw_data!B3,2))),DATE(VALUE(RIGHT(raw_data!B3,4)),MATCH(MID(raw_data!B3,4,3),{"Jan","Feb","Mar","Apr","May","Jun","Jul","Aug","Sep","Oct","Nov","Dec"},0),VALUE(LEFT(raw_data!B3,2)))))),"") -> 45535 | C3: =IFERROR(IF(MID(raw_data!C3,3,1)="/",DATE(VALUE(RIGHT(raw_data!C3,4)),VALUE(LEFT(raw_data!C3,2)),VALUE(MID(raw_data!C3,4,2))),IF(MID(raw_data!C3,3,1)="-",DATE(VALUE(RIGHT(raw_data!C3,4)),VALUE(MID(raw_data!C3,4,2)),VALUE(LEFT(raw_data!C3,2))),IF(MID(raw_data!C3,5,1)="-",DATE(VALUE(LEFT(raw_data!C3,4)),VALUE(MID(raw_data!C3,6,2)),VALUE(RIGHT(raw_data!C3,2))),DATE(VALUE(RIGHT(raw_data!C3,4)),MATCH(MID(raw_data!C3,4,3),{"Jan","Feb","Mar","Apr","May","Jun","Jul","Aug","Sep","Oct","Nov","Dec"},0),VALUE(LEFT(raw_data!C3,2)))))),"") -> 45540 | D3: =IF(TRIM(raw_data!B3)="","Missing",IF(B3="","Invalid/Unrecognized","Valid")) -> Valid | E3: =IF(TRIM(raw_data!C3)="","Missing",IF(C3="","Invalid/Unrecognized","Valid")) -> Valid | F3: =IF(OR(B3="",C3=""),"",C3-B3) -> 5 | G3: =IF(F3="","N/A",IF(F3<0,"Invalid - Ship Before Order","OK")) -> OK | H3: =raw_data!D3 -> CUST-2054 | I3: =PROPER(TRIM(raw_data!E3)) -> Mira Das | J3: =PROPER(TRIM(raw_data!F3)) -> Small Business | K3: =IF(TRIM(raw_data!G3)="","Unknown",PROPER(TRIM(raw_data!G3))) -> East | L3: =IF(TRIM(raw_data!G3)="","Filled - Unknown","OK") -> OK | M3: =PROPER(TRIM(raw_data!H3)) -> Odisha | N3: =PROPER(TRIM(raw_data!I3)) -> Bhubaneswar | O3: =PROPER(TRIM(raw_data!J3)) -> Furniture | P3: =PROPER(TRIM(raw_data!K3)) -> Tables | Q3: =TRIM(raw_data!L3) -> Pro Tables 258 | R3: =IF(TRIM(raw_data!M3)="","Unknown",PROPER(TRIM(raw_data!M3))) -> Same Day | S3: =IF(TRIM(raw_data!M3)="","Filled - Unknown","OK") -> OK | T3: =raw_data!N3 -> 3 | U3: =raw_data!O3 -> 2437.5 | V3: =raw_data!P3 -> 0 | W3: =IF(raw_data!P3="",0,IF(ISTEXT(raw_data!P3),IF(RIGHT(raw_data!P3,1)="%",VALUE(LEFT(raw_data!P3,LEN(raw_data!P3)-1))/100,VALUE(raw_data!P3)),raw_data!P3)) -> 0 | X3: =IF(raw_data!P3="","Missing - Defaulted to 0",IF(W3<0,"Negative - Invalid",IF(W3>0.3,"Above Allowed Range - Invalid","Valid"))) -> Valid | Y3: =raw_data!Q3 -> 7312.5 | Z3: =raw_data!R3 -> 4904.73 | AA3: =raw_data!S3 -> 2407.77 | AB3: =PROPER(TRIM(raw_data!T3)) -> Paid | AC3: =PROPER(TRIM(raw_data!U3)) -> Completed | AD3: =T3*U3*(1-W3) -> 7312.5 | AE3: =AD3-Z3 -> 2407.77 | AF3: =IF(AD3=0,0,AE3/AD3) -> 0.32926769 | AG3: =IF(ABS(Y3-AD3)>1,"Mismatch","OK") -> OK | AH3: =IF(ABS(AA3-AE3)>1,"Mismatch","OK") -> OK | AI3: =IF(B3="","",MONTH(B3)) -> 8 | AJ3: =IF(B3="","",YEAR(B3)) -> 2024 | AK3: =IF(COUNTIF(raw_data!$A$2:$A$913,A3)>1,"Conflicting Duplicate - Flagged for Review","Unique") -> Unique | AL3: =IF(AB3="Refunded","Yes","No") -> No | AM3: =IF(OR(AC3<>"Completed",AB3="Failed"),"Excluded","Included") -> Included | AN3: =IF(OR(D3="Invalid/Unrecognized",E3="Invalid/Unrecognized",G3="Invalid - Ship Before Order",X3="Negative - Invalid",X3="Above Allowed Range - Invalid",AG3="Mismatch",AH3="Mismatch",AK3="Conflicting Duplicate - Flagged for Review"),"Invalid",IF(OR(L3="Filled - Unknown",S3="Filled - Unknown",X3="Missing - Defaulted to 0",AL3="Yes",AC3="Cancelled",AC3="Returned"),"Warning","Clean")) -> Clean
A4: =raw_data!A4 -> ORD-2024-10003 | B4: =IFERROR(IF(MID(raw_data!B4,3,1)="/",DATE(VALUE(RIGHT(raw_data!B4,4)),VALUE(LEFT(raw_data!B4,2)),VALUE(MID(raw_data!B4,4,2))),IF(MID(raw_data!B4,3,1)="-",DATE(VALUE(RIGHT(raw_data!B4,4)),VALUE(MID(raw_data!B4,4,2)),VALUE(LEFT(raw_data!B4,2))),IF(MID(raw_data!B4,5,1)="-",DATE(VALUE(LEFT(raw_data!B4,4)),VALUE(MID(raw_data!B4,6,2)),VALUE(RIGHT(raw_data!B4,2))),DATE(VALUE(RIGHT(raw_data!B4,4)),MATCH(MID(raw_data!B4,4,3),{"Jan","Feb","Mar","Apr","May","Jun","Jul","Aug","Sep","Oct","Nov","Dec"},0),VALUE(LEFT(raw_data!B4,2)))))),"") -> 45451 | C4: =IFERROR(IF(MID(raw_data!C4,3,1)="/",DATE(VALUE(RIGHT(raw_data!C4,4)),VALUE(LEFT(raw_data!C4,2)),VALUE(MID(raw_data!C4,4,2))),IF(MID(raw_data!C4,3,1)="-",DATE(VALUE(RIGHT(raw_data!C4,4)),VALUE(MID(raw_data!C4,4,2)),VALUE(LEFT(raw_data!C4,2))),IF(MID(raw_data!C4,5,1)="-",DATE(VALUE(LEFT(raw_data!C4,4)),VALUE(MID(raw_data!C4,6,2)),VALUE(RIGHT(raw_data!C4,2))),DATE(VALUE(RIGHT(raw_data!C4,4)),MATCH(MID(raw_data!C4,4,3),{"Jan","Feb","Mar","Apr","May","Jun","Jul","Aug","Sep","Oct","Nov","Dec"},0),VALUE(LEFT(raw_data!C4,2)))))),"") -> 45458 | D4: =IF(TRIM(raw_data!B4)="","Missing",IF(B4="","Invalid/Unrecognized","Valid")) -> Valid | E4: =IF(TRIM(raw_data!C4)="","Missing",IF(C4="","Invalid/Unrecognized","Valid")) -> Valid | F4: =IF(OR(B4="",C4=""),"",C4-B4) -> 7 | G4: =IF(F4="","N/A",IF(F4<0,"Invalid - Ship Before Order","OK")) -> OK | H4: =raw_data!D4 -> CUST-6843 | I4: =PROPER(TRIM(raw_data!E4)) -> Isha Nair | J4: =PROPER(TRIM(raw_data!F4)) -> Consumer | K4: =IF(TRIM(raw_data!G4)="","Unknown",PROPER(TRIM(raw_data!G4))) -> East | L4: =IF(TRIM(raw_data!G4)="","Filled - Unknown","OK") -> OK | M4: =PROPER(TRIM(raw_data!H4)) -> Odisha | N4: =PROPER(TRIM(raw_data!I4)) -> Bhubaneswar | O4: =PROPER(TRIM(raw_data!J4)) -> Office Supplies | P4: =PROPER(TRIM(raw_data!K4)) -> Art | Q4: =TRIM(raw_data!L4) -> Elite Art 525 | R4: =IF(TRIM(raw_data!M4)="","Unknown",PROPER(TRIM(raw_data!M4))) -> First Class | S4: =IF(TRIM(raw_data!M4)="","Filled - Unknown","OK") -> OK | T4: =raw_data!N4 -> 4 | U4: =raw_data!O4 -> 1065.43 | V4: =raw_data!P4 -> 0.55 | W4: =IF(raw_data!P4="",0,IF(ISTEXT(raw_data!P4),IF(RIGHT(raw_data!P4,1)="%",VALUE(LEFT(raw_data!P4,LEN(raw_data!P4)-1))/100,VALUE(raw_data!P4)),raw_data!P4)) -> 0.55 | X4: =IF(raw_data!P4="","Missing - Defaulted to 0",IF(W4<0,"Negative - Invalid",IF(W4>0.3,"Above Allowed Range - Invalid","Valid"))) -> Above Allowed Range - Invalid | Y4: =raw_data!Q4 -> 4261.72 | Z4: =raw_data!R4 -> 2465.69 | AA4: =raw_data!S4 -> 1796.03 | AB4: =PROPER(TRIM(raw_data!T4)) -> Paid | AC4: =PROPER(TRIM(raw_data!U4)) -> Completed | AD4: =T4*U4*(1-W4) -> 1917.774 | AE4: =AD4-Z4 -> -547.916 | AF4: =IF(AD4=0,0,AE4/AD4) -> -0.28570415 | AG4: =IF(ABS(Y4-AD4)>1,"Mismatch","OK") -> Mismatch | AH4: =IF(ABS(AA4-AE4)>1,"Mismatch","OK") -> Mismatch | AI4: =IF(B4="","",MONTH(B4)) -> 6 | AJ4: =IF(B4="","",YEAR(B4)) -> 2024 | AK4: =IF(COUNTIF(raw_data!$A$2:$A$913,A4)>1,"Conflicting Duplicate - Flagged for Review","Unique") -> Unique | AL4: =IF(AB4="Refunded","Yes","No") -> No | AM4: =IF(OR(AC4<>"Completed",AB4="Failed"),"Excluded","Included") -> Included | AN4: =IF(OR(D4="Invalid/Unrecognized",E4="Invalid/Unrecognized",G4="Invalid - Ship Before Order",X4="Negative - Invalid",X4="Above Allowed Range - Invalid",AG4="Mismatch",AH4="Mismatch",AK4="Conflicting Duplicate - Flagged for Review"),"Invalid",IF(OR(L4="Filled - Unknown",S4="Filled - Unknown",X4="Missing - Defaulted to 0",AL4="Yes",AC4="Cancelled",AC4="Returned"),"Warning","Clean")) -> Invalid
A5: =raw_data!A5 -> ORD-2024-10004 | B5: =IFERROR(IF(MID(raw_data!B5,3,1)="/",DATE(VALUE(RIGHT(raw_data!B5,4)),VALUE(LEFT(raw_data!B5,2)),VALUE(MID(raw_data!B5,4,2))),IF(MID(raw_data!B5,3,1)="-",DATE(VALUE(RIGHT(raw_data!B5,4)),VALUE(MID(raw_data!B5,4,2)),VALUE(LEFT(raw_data!B5,2))),IF(MID(raw_data!B5,5,1)="-",DATE(VALUE(LEFT(raw_data!B5,4)),VALUE(MID(raw_data!B5,6,2)),VALUE(RIGHT(raw_data!B5,2))),DATE(VALUE(RIGHT(raw_data!B5,4)),MATCH(MID(raw_data!B5,4,3),{"Jan","Feb","Mar","Apr","May","Jun","Jul","Aug","Sep","Oct","Nov","Dec"},0),VALUE(LEFT(raw_data!B5,2)))))),"") -> 45624 | C5: =IFERROR(IF(MID(raw_data!C5,3,1)="/",DATE(VALUE(RIGHT(raw_data!C5,4)),VALUE(LEFT(raw_data!C5,2)),VALUE(MID(raw_data!C5,4,2))),IF(MID(raw_data!C5,3,1)="-",DATE(VALUE(RIGHT(raw_data!C5,4)),VALUE(MID(raw_data!C5,4,2)),VALUE(LEFT(raw_data!C5,2))),IF(MID(raw_data!C5,5,1)="-",DATE(VALUE(LEFT(raw_data!C5,4)),VALUE(MID(raw_data!C5,6,2)),VALUE(RIGHT(raw_data!C5,2))),DATE(VALUE(RIGHT(raw_data!C5,4)),MATCH(MID(raw_data!C5,4,3),{"Jan","Feb","Mar","Apr","May","Jun","Jul","Aug","Sep","Oct","Nov","Dec"},0),VALUE(LEFT(raw_data!C5,2)))))),"") -> 45625 | D5: =IF(TRIM(raw_data!B5)="","Missing",IF(B5="","Invalid/Unrecognized","Valid")) -> Valid | E5: =IF(TRIM(raw_data!C5)="","Missing",IF(C5="","Invalid/Unrecognized","Valid")) -> Valid | F5: =IF(OR(B5="",C5=""),"",C5-B5) -> 1 | G5: =IF(F5="","N/A",IF(F5<0,"Invalid - Ship Before Order","OK")) -> OK | H5: =raw_data!D5 -> CUST-3722 | I5: =PROPER(TRIM(raw_data!E5)) -> Arjun Bose | J5: =PROPER(TRIM(raw_data!F5)) -> Small Business | K5: =IF(TRIM(raw_data!G5)="","Unknown",PROPER(TRIM(raw_data!G5))) -> South | L5: =IF(TRIM(raw_data!G5)="","Filled - Unknown","OK") -> OK | M5: =PROPER(TRIM(raw_data!H5)) -> Telangana | N5: =PROPER(TRIM(raw_data!I5)) -> Hyderabad | O5: =PROPER(TRIM(raw_data!J5)) -> Furniture | P5: =PROPER(TRIM(raw_data!K5)) -> Furnishings | Q5: =TRIM(raw_data!L5) -> Smart Furnishings 294 | R5: =IF(TRIM(raw_data!M5)="","Unknown",PROPER(TRIM(raw_data!M5))) -> Standard Class | S5: =IF(TRIM(raw_data!M5)="","Filled - Unknown","OK") -> OK | T5: =raw_data!N5 -> 6 | U5: =raw_data!O5 -> 1848.43 | V5: =raw_data!P5 -> 0.25 | W5: =IF(raw_data!P5="",0,IF(ISTEXT(raw_data!P5),IF(RIGHT(raw_data!P5,1)="%",VALUE(LEFT(raw_data!P5,LEN(raw_data!P5)-1))/100,VALUE(raw_data!P5)),raw_data!P5)) -> 0.25 | X5: =IF(raw_data!P5="","Missing - Defaulted to 0",IF(W5<0,"Negative - Invalid",IF(W5>0.3,"Above Allowed Range - Invalid","Valid"))) -> Valid | Y5: =raw_data!Q5 -> 8317.93 | Z5: =raw_data!R5 -> 6796.77 | AA5: =raw_data!S5 -> 1521.16 | AB5: =PROPER(TRIM(raw_data!T5)) -> Paid | AC5: =PROPER(TRIM(raw_data!U5)) -> Completed | AD5: =T5*U5*(1-W5) -> 8317.935 | AE5: =AD5-Z5 -> 1521.165 | AF5: =IF(AD5=0,0,AE5/AD5) -> 0.18287772 | AG5: =IF(ABS(Y5-AD5)>1,"Mismatch","OK") -> OK | AH5: =IF(ABS(AA5-AE5)>1,"Mismatch","OK") -> OK | AI5: =IF(B5="","",MONTH(B5)) -> 11 | AJ5: =IF(B5="","",YEAR(B5)) -> 2024 | AK5: =IF(COUNTIF(raw_data!$A$2:$A$913,A5)>1,"Conflicting Duplicate - Flagged for Review","Unique") -> Unique | AL5: =IF(AB5="Refunded","Yes","No") -> No | AM5: =IF(OR(AC5<>"Completed",AB5="Failed"),"Excluded","Included") -> Included | AN5: =IF(OR(D5="Invalid/Unrecognized",E5="Invalid/Unrecognized",G5="Invalid - Ship Before Order",X5="Negative - Invalid",X5="Above Allowed Range - Invalid",AG5="Mismatch",AH5="Mismatch",AK5="Conflicting Duplicate - Flagged for Review"),"Invalid",IF(OR(L5="Filled - Unknown",S5="Filled - Unknown",X5="Missing - Defaulted to 0",AL5="Yes",AC5="Cancelled",AC5="Returned"),"Warning","Clean")) -> Clean
A6: =raw_data!A6 -> ORD-2025-10005 | B6: =IFERROR(IF(MID(raw_data!B6,3,1)="/",DATE(VALUE(RIGHT(raw_data!B6,4)),VALUE(LEFT(raw_data!B6,2)),VALUE(MID(raw_data!B6,4,2))),IF(MID(raw_data!B6,3,1)="-",DATE(VALUE(RIGHT(raw_data!B6,4)),VALUE(MID(raw_data!B6,4,2)),VALUE(LEFT(raw_data!B6,2))),IF(MID(raw_data!B6,5,1)="-",DATE(VALUE(LEFT(raw_data!B6,4)),VALUE(MID(raw_data!B6,6,2)),VALUE(RIGHT(raw_data!B6,2))),DATE(VALUE(RIGHT(raw_data!B6,4)),MATCH(MID(raw_data!B6,4,3),{"Jan","Feb","Mar","Apr","May","Jun","Jul","Aug","Sep","Oct","Nov","Dec"},0),VALUE(LEFT(raw_data!B6,2)))))),"") -> 45898 | C6: =IFERROR(IF(MID(raw_data!C6,3,1)="/",DATE(VALUE(RIGHT(raw_data!C6,4)),VALUE(LEFT(raw_data!C6,2)),VALUE(MID(raw_data!C6,4,2))),IF(MID(raw_data!C6,3,1)="-",DATE(VALUE(RIGHT(raw_data!C6,4)),VALUE(MID(raw_data!C6,4,2)),VALUE(LEFT(raw_data!C6,2))),IF(MID(raw_data!C6,5,1)="-",DATE(VALUE(LEFT(raw_data!C6,4)),VALUE(MID(raw_data!C6,6,2)),VALUE(RIGHT(raw_data!C6,2))),DATE(VALUE(RIGHT(raw_data!C6,4)),MATCH(MID(raw_data!C6,4,3),{"Jan","Feb","Mar","Apr","May","Jun","Jul","Aug","Sep","Oct","Nov","Dec"},0),VALUE(LEFT(raw_data!C6,2)))))),"") -> 45901 | D6: =IF(TRIM(raw_data!B6)="","Missing",IF(B6="","Invalid/Unrecognized","Valid")) -> Valid | E6: =IF(TRIM(raw_data!C6)="","Missing",IF(C6="","Invalid/Unrecognized","Valid")) -> Valid | F6: =IF(OR(B6="",C6=""),"",C6-B6) -> 3 | G6: =IF(F6="","N/A",IF(F6<0,"Invalid - Ship Before Order","OK")) -> OK | H6: =raw_data!D6 -> CUST-8130 | I6: =PROPER(TRIM(raw_data!E6)) -> Ananya Rao | J6: =PROPER(TRIM(raw_data!F6)) -> Small Business | K6: =IF(TRIM(raw_data!G6)="","Unknown",PROPER(TRIM(raw_data!G6))) -> West | L6: =IF(TRIM(raw_data!G6)="","Filled - Unknown","OK") -> OK | M6: =PROPER(TRIM(raw_data!H6)) -> Maharashtra | N6: =PROPER(TRIM(raw_data!I6)) -> Mumbai | O6: =PROPER(TRIM(raw_data!J6)) -> Furniture | P6: =PROPER(TRIM(raw_data!K6)) -> Chairs | Q6: =TRIM(raw_data!L6) -> Elite Chairs 543 | R6: =IF(TRIM(raw_data!M6)="","Unknown",PROPER(TRIM(raw_data!M6))) -> First Class | S6: =IF(TRIM(raw_data!M6)="","Filled - Unknown","OK") -> OK | T6: =raw_data!N6 -> 7 | U6: =raw_data!O6 -> 2973.76 | V6: =raw_data!P6 -> 0 | W6: =IF(raw_data!P6="",0,IF(ISTEXT(raw_data!P6),IF(RIGHT(raw_data!P6,1)="%",VALUE(LEFT(raw_data!P6,LEN(raw_data!P6)-1))/100,VALUE(raw_data!P6)),raw_data!P6)) -> 0 | X6: =IF(raw_data!P6="","Missing - Defaulted to 0",IF(W6<0,"Negative - Invalid",IF(W6>0.3,"Above Allowed Range - Invalid","Valid"))) -> Valid | Y6: =raw_data!Q6 -> 20816.32 | Z6: =raw_data!R6 -> 17705.37 | AA6: =raw_data!S6 -> 3110.95 | AB6: =PROPER(TRIM(raw_data!T6)) -> Paid | AC6: =PROPER(TRIM(raw_data!U6)) -> Cancelled | AD6: =T6*U6*(1-W6) -> 20816.32 | AE6: =AD6-Z6 -> 3110.95 | AF6: =IF(AD6=0,0,AE6/AD6) -> 0.14944764 | AG6: =IF(ABS(Y6-AD6)>1,"Mismatch","OK") -> OK | AH6: =IF(ABS(AA6-AE6)>1,"Mismatch","OK") -> OK | AI6: =IF(B6="","",MONTH(B6)) -> 8 | AJ6: =IF(B6="","",YEAR(B6)) -> 2025 | AK6: =IF(COUNTIF(raw_data!$A$2:$A$913,A6)>1,"Conflicting Duplicate - Flagged for Review","Unique") -> Unique | AL6: =IF(AB6="Refunded","Yes","No") -> No | AM6: =IF(OR(AC6<>"Completed",AB6="Failed"),"Excluded","Included") -> Excluded | AN6: =IF(OR(D6="Invalid/Unrecognized",E6="Invalid/Unrecognized",G6="Invalid - Ship Before Order",X6="Negative - Invalid",X6="Above Allowed Range - Invalid",AG6="Mismatch",AH6="Mismatch",AK6="Conflicting Duplicate - Flagged for Review"),"Invalid",IF(OR(L6="Filled - Unknown",S6="Filled - Unknown",X6="Missing - Defaulted to 0",AL6="Yes",AC6="Cancelled",AC6="Returned"),"Warning","Clean")) -> Warning
A7: =raw_data!A7 -> ORD-2024-10006 | B7: =IFERROR(IF(MID(raw_data!B7,3,1)="/",DATE(VALUE(RIGHT(raw_data!B7,4)),VALUE(LEFT(raw_data!B7,2)),VALUE(MID(raw_data!B7,4,2))),IF(MID(raw_data!B7,3,1)="-",DATE(VALUE(RIGHT(raw_data!B7,4)),VALUE(MID(raw_data!B7,4,2)),VALUE(LEFT(raw_data!B7,2))),IF(MID(raw_data!B7,5,1)="-",DATE(VALUE(LEFT(raw_data!B7,4)),VALUE(MID(raw_data!B7,6,2)),VALUE(RIGHT(raw_data!B7,2))),DATE(VALUE(RIGHT(raw_data!B7,4)),MATCH(MID(raw_data!B7,4,3),{"Jan","Feb","Mar","Apr","May","Jun","Jul","Aug","Sep","Oct","Nov","Dec"},0),VALUE(LEFT(raw_data!B7,2)))))),"") -> 45436 | C7: =IFERROR(IF(MID(raw_data!C7,3,1)="/",DATE(VALUE(RIGHT(raw_data!C7,4)),VALUE(LEFT(raw_data!C7,2)),VALUE(MID(raw_data!C7,4,2))),IF(MID(raw_data!C7,3,1)="-",DATE(VALUE(RIGHT(raw_data!C7,4)),VALUE(MID(raw_data!C7,4,2)),VALUE(LEFT(raw_data!C7,2))),IF(MID(raw_data!C7,5,1)="-",DATE(VALUE(LEFT(raw_data!C7,4)),VALUE(MID(raw_data!C7,6,2)),VALUE(RIGHT(raw_data!C7,2))),DATE(VALUE(RIGHT(raw_data!C7,4)),MATCH(MID(raw_data!C7,4,3),{"Jan","Feb","Mar","Apr","May","Jun","Jul","Aug","Sep","Oct","Nov","Dec"},0),VALUE(LEFT(raw_data!C7,2)))))),"") -> 45440 | D7: =IF(TRIM(raw_data!B7)="","Missing",IF(B7="","Invalid/Unrecognized","Valid")) -> Valid | E7: =IF(TRIM(raw_data!C7)="","Missing",IF(C7="","Invalid/Unrecognized","Valid")) -> Valid | F7: =IF(OR(B7="",C7=""),"",C7-B7) -> 4 | G7: =IF(F7="","N/A",IF(F7<0,"Invalid - Ship Before Order","OK")) -> OK | H7: =raw_data!D7 -> CUST-6056 | I7: =PROPER(TRIM(raw_data!E7)) -> Vikram Iyer | J7: =PROPER(TRIM(raw_data!F7)) -> Small Business | K7: =IF(TRIM(raw_data!G7)="","Unknown",PROPER(TRIM(raw_data!G7))) -> West | L7: =IF(TRIM(raw_data!G7)="","Filled - Unknown","OK") -> OK | M7: =PROPER(TRIM(raw_data!H7)) -> Madhya Pradesh | N7: =PROPER(TRIM(raw_data!I7)) -> Indore | O7: =PROPER(TRIM(raw_data!J7)) -> Technology | P7: =PROPER(TRIM(raw_data!K7)) -> Accessories | Q7: =TRIM(raw_data!L7) -> Pro Accessories 821 | R7: =IF(TRIM(raw_data!M7)="","Unknown",PROPER(TRIM(raw_data!M7))) -> Same Day | S7: =IF(TRIM(raw_data!M7)="","Filled - Unknown","OK") -> OK | T7: =raw_data!N7 -> 3 | U7: =raw_data!O7 -> 1053.11 | V7: =raw_data!P7 -> 0.2 | W7: =IF(raw_data!P7="",0,IF(ISTEXT(raw_data!P7),IF(RIGHT(raw_data!P7,1)="%",VALUE(LEFT(raw_data!P7,LEN(raw_data!P7)-1))/100,VALUE(raw_data!P7)),raw_data!P7)) -> 0.2 | X7: =IF(raw_data!P7="","Missing - Defaulted to 0",IF(W7<0,"Negative - Invalid",IF(W7>0.3,"Above Allowed Range - Invalid","Valid"))) -> Valid | Y7: =raw_data!Q7 -> 2527.46 | Z7: =raw_data!R7 -> 1533.58 | AA7: =raw_data!S7 -> 993.88 | AB7: =PROPER(TRIM(raw_data!T7)) -> Paid | AC7: =PROPER(TRIM(raw_data!U7)) -> Completed | AD7: =T7*U7*(1-W7) -> 2527.464 | AE7: =AD7-Z7 -> 993.884 | AF7: =IF(AD7=0,0,AE7/AD7) -> 0.39323369 | AG7: =IF(ABS(Y7-AD7)>1,"Mismatch","OK") -> OK | AH7: =IF(ABS(AA7-AE7)>1,"Mismatch","OK") -> OK | AI7: =IF(B7="","",MONTH(B7)) -> 5 | AJ7: =IF(B7="","",YEAR(B7)) -> 2024 | AK7: =IF(COUNTIF(raw_data!$A$2:$A$913,A7)>1,"Conflicting Duplicate - Flagged for Review","Unique") -> Unique | AL7: =IF(AB7="Refunded","Yes","No") -> No | AM7: =IF(OR(AC7<>"Completed",AB7="Failed"),"Excluded","Included") -> Included | AN7: =IF(OR(D7="Invalid/Unrecognized",E7="Invalid/Unrecognized",G7="Invalid - Ship Before Order",X7="Negative - Invalid",X7="Above Allowed Range - Invalid",AG7="Mismatch",AH7="Mismatch",AK7="Conflicting Duplicate - Flagged for Review"),"Invalid",IF(OR(L7="Filled - Unknown",S7="Filled - Unknown",X7="Missing - Defaulted to 0",AL7="Yes",AC7="Cancelled",AC7="Returned"),"Warning","Clean")) -> Clean
A8: =raw_data!A8 -> ORD-2025-10007 | B8: =IFERROR(IF(MID(raw_data!B8,3,1)="/",DATE(VALUE(RIGHT(raw_data!B8,4)),VALUE(LEFT(raw_data!B8,2)),VALUE(MID(raw_data!B8,4,2))),IF(MID(raw_data!B8,3,1)="-",DATE(VALUE(RIGHT(raw_data!B8,4)),VALUE(MID(raw_data!B8,4,2)),VALUE(LEFT(raw_data!B8,2))),IF(MID(raw_data!B8,5,1)="-",DATE(VALUE(LEFT(raw_data!B8,4)),VALUE(MID(raw_data!B8,6,2)),VALUE(RIGHT(raw_data!B8,2))),DATE(VALUE(RIGHT(raw_data!B8,4)),MATCH(MID(raw_data!B8,4,3),{"Jan","Feb","Mar","Apr","May","Jun","Jul","Aug","Sep","Oct","Nov","Dec"},0),VALUE(LEFT(raw_data!B8,2)))))),"") -> 45757 | C8: =IFERROR(IF(MID(raw_data!C8,3,1)="/",DATE(VALUE(RIGHT(raw_data!C8,4)),VALUE(LEFT(raw_data!C8,2)),VALUE(MID(raw_data!C8,4,2))),IF(MID(raw_data!C8,3,1)="-",DATE(VALUE(RIGHT(raw_data!C8,4)),VALUE(MID(raw_data!C8,4,2)),VALUE(LEFT(raw_data!C8,2))),IF(MID(raw_data!C8,5,1)="-",DATE(VALUE(LEFT(raw_data!C8,4)),VALUE(MID(raw_data!C8,6,2)),VALUE(RIGHT(raw_data!C8,2))),DATE(VALUE(RIGHT(raw_data!C8,4)),MATCH(MID(raw_data!C8,4,3),{"Jan","Feb","Mar","Apr","May","Jun","Jul","Aug","Sep","Oct","Nov","Dec"},0),VALUE(LEFT(raw_data!C8,2)))))),"") -> 45763 | D8: =IF(TRIM(raw_data!B8)="","Missing",IF(B8="","Invalid/Unrecognized","Valid")) -> Valid | E8: =IF(TRIM(raw_data!C8)="","Missing",IF(C8="","Invalid/Unrecognized","Valid")) -> Valid | F8: =IF(OR(B8="",C8=""),"",C8-B8) -> 6 | G8: =IF(F8="","N/A",IF(F8<0,"Invalid - Ship Before Order","OK")) -> OK | H8: =raw_data!D8 -> CUST-3656 | I8: =PROPER(TRIM(raw_data!E8)) -> Neha Gupta | J8: =PROPER(TRIM(raw_data!F8)) -> Consumer | K8: =IF(TRIM(raw_data!G8)="","Unknown",PROPER(TRIM(raw_data!G8))) -> East | L8: =IF(TRIM(raw_data!G8)="","Filled - Unknown","OK") -> OK | M8: =PROPER(TRIM(raw_data!H8)) -> Odisha | N8: =PROPER(TRIM(raw_data!I8)) -> Bhubaneswar | O8: =PROPER(TRIM(raw_data!J8)) -> Technology | P8: =PROPER(TRIM(raw_data!K8)) -> Copiers | Q8: =TRIM(raw_data!L8) -> Eco Copiers 790 | R8: =IF(TRIM(raw_data!M8)="","Unknown",PROPER(TRIM(raw_data!M8))) -> Standard Class | S8: =IF(TRIM(raw_data!M8)="","Filled - Unknown","OK") -> OK | T8: =raw_data!N8 -> 4 | U8: =raw_data!O8 -> 1719.87 | V8: =raw_data!P8 -> 0.15 | W8: =IF(raw_data!P8="",0,IF(ISTEXT(raw_data!P8),IF(RIGHT(raw_data!P8,1)="%",VALUE(LEFT(raw_data!P8,LEN(raw_data!P8)-1))/100,VALUE(raw_data!P8)),raw_data!P8)) -> 0.15 | X8: =IF(raw_data!P8="","Missing - Defaulted to 0",IF(W8<0,"Negative - Invalid",IF(W8>0.3,"Above Allowed Range - Invalid","Valid"))) -> Valid | Y8: =raw_data!Q8 -> 5847.56 | Z8: =raw_data!R8 -> 4727.25 | AA8: =raw_data!S8 -> 1120.31 | AB8: =PROPER(TRIM(raw_data!T8)) -> Paid | AC8: =PROPER(TRIM(raw_data!U8)) -> Completed | AD8: =T8*U8*(1-W8) -> 5847.558 | AE8: =AD8-Z8 -> 1120.308 | AF8: =IF(AD8=0,0,AE8/AD8) -> 0.19158562 | AG8: =IF(ABS(Y8-AD8)>1,"Mismatch","OK") -> OK | AH8: =IF(ABS(AA8-AE8)>1,"Mismatch","OK") -> OK | AI8: =IF(B8="","",MONTH(B8)) -> 4 | AJ8: =IF(B8="","",YEAR(B8)) -> 2025 | AK8: =IF(COUNTIF(raw_data!$A$2:$A$913,A8)>1,"Conflicting Duplicate - Flagged for Review","Unique") -> Unique | AL8: =IF(AB8="Refunded","Yes","No") -> No | AM8: =IF(OR(AC8<>"Completed",AB8="Failed"),"Excluded","Included") -> Included | AN8: =IF(OR(D8="Invalid/Unrecognized",E8="Invalid/Unrecognized",G8="Invalid - Ship Before Order",X8="Negative - Invalid",X8="Above Allowed Range - Invalid",AG8="Mismatch",AH8="Mismatch",AK8="Conflicting Duplicate - Flagged for Review"),"Invalid",IF(OR(L8="Filled - Unknown",S8="Filled - Unknown",X8="Missing - Defaulted to 0",AL8="Yes",AC8="Cancelled",AC8="Returned"),"Warning","Clean")) -> Clean
A9: =raw_data!A9 -> ORD-2025-10008 | B9: =IFERROR(IF(MID(raw_data!B9,3,1)="/",DATE(VALUE(RIGHT(raw_data!B9,4)),VALUE(LEFT(raw_data!B9,2)),VALUE(MID(raw_data!B9,4,2))),IF(MID(raw_data!B9,3,1)="-",DATE(VALUE(RIGHT(raw_data!B9,4)),VALUE(MID(raw_data!B9,4,2)),VALUE(LEFT(raw_data!B9,2))),IF(MID(raw_data!B9,5,1)="-",DATE(VALUE(LEFT(raw_data!B9,4)),VALUE(MID(raw_data!B9,6,2)),VALUE(RIGHT(raw_data!B9,2))),DATE(VALUE(RIGHT(raw_data!B9,4)),MATCH(MID(raw_data!B9,4,3),{"Jan","Feb","Mar","Apr","May","Jun","Jul","Aug","Sep","Oct","Nov","Dec"},0),VALUE(LEFT(raw_data!B9,2)))))),"") -> 45711 | C9: =IFERROR(IF(MID(raw_data!C9,3,1)="/",DATE(VALUE(RIGHT(raw_data!C9,4)),VALUE(LEFT(raw_data!C9,2)),VALUE(MID(raw_data!C9,4,2))),IF(MID(raw_data!C9,3,1)="-",DATE(VALUE(RIGHT(raw_data!C9,4)),VALUE(MID(raw_data!C9,4,2)),VALUE(LEFT(raw_data!C9,2))),IF(MID(raw_data!C9,5,1)="-",DATE(VALUE(LEFT(raw_data!C9,4)),VALUE(MID(raw_data!C9,6,2)),VALUE(RIGHT(raw_data!C9,2))),DATE(VALUE(RIGHT(raw_data!C9,4)),MATCH(MID(raw_data!C9,4,3),{"Jan","Feb","Mar","Apr","May","Jun","Jul","Aug","Sep","Oct","Nov","Dec"},0),VALUE(LEFT(raw_data!C9,2)))))),"") -> 45714 | D9: =IF(TRIM(raw_data!B9)="","Missing",IF(B9="","Invalid/Unrecognized","Valid")) -> Valid | E9: =IF(TRIM(raw_data!C9)="","Missing",IF(C9="","Invalid/Unrecognized","Valid")) -> Valid | F9: =IF(OR(B9="",C9=""),"",C9-B9) -> 3 | G9: =IF(F9="","N/A",IF(F9<0,"Invalid - Ship Before Order","OK")) -> OK | H9: =raw_data!D9 -> CUST-4683 | I9: =PROPER(TRIM(raw_data!E9)) -> Isha Nair | J9: =PROPER(TRIM(raw_data!F9)) -> Small Business | K9: =IF(TRIM(raw_data!G9)="","Unknown",PROPER(TRIM(raw_data!G9))) -> South | L9: =IF(TRIM(raw_data!G9)="","Filled - Unknown","OK") -> OK | M9: =PROPER(TRIM(raw_data!H9)) -> Andhra Pradesh | N9: =PROPER(TRIM(raw_data!I9)) -> Vijayawada | O9: =PROPER(TRIM(raw_data!J9)) -> Office Supplies | P9: =PROPER(TRIM(raw_data!K9)) -> Art | Q9: =TRIM(raw_data!L9) -> Eco Art 848 | R9: =IF(TRIM(raw_data!M9)="","Unknown",PROPER(TRIM(raw_data!M9))) -> First Class | S9: =IF(TRIM(raw_data!M9)="","Filled - Unknown","OK") -> OK | T9: =raw_data!N9 -> 1 | U9: =raw_data!O9 -> 2980.71 | V9: =raw_data!P9 -> 0 | W9: =IF(raw_data!P9="",0,IF(ISTEXT(raw_data!P9),IF(RIGHT(raw_data!P9,1)="%",VALUE(LEFT(raw_data!P9,LEN(raw_data!P9)-1))/100,VALUE(raw_data!P9)),raw_data!P9)) -> 0 | X9: =IF(raw_data!P9="","Missing - Defaulted to 0",IF(W9<0,"Negative - Invalid",IF(W9>0.3,"Above Allowed Range - Invalid","Valid"))) -> Valid | Y9: =raw_data!Q9 -> 2980.71 | Z9: =raw_data!R9 -> 2357.22 | AA9: =raw_data!S9 -> 623.49 | AB9: =PROPER(TRIM(raw_data!T9)) -> Paid | AC9: =PROPER(TRIM(raw_data!U9)) -> Completed | AD9: =T9*U9*(1-W9) -> 2980.71 | AE9: =AD9-Z9 -> 623.49 | AF9: =IF(AD9=0,0,AE9/AD9) -> 0.209175 | AG9: =IF(ABS(Y9-AD9)>1,"Mismatch","OK") -> OK | AH9: =IF(ABS(AA9-AE9)>1,"Mismatch","OK") -> OK | AI9: =IF(B9="","",MONTH(B9)) -> 2 | AJ9: =IF(B9="","",YEAR(B9)) -> 2025 | AK9: =IF(COUNTIF(raw_data!$A$2:$A$913,A9)>1,"Conflicting Duplicate - Flagged for Review","Unique") -> Unique | AL9: =IF(AB9="Refunded","Yes","No") -> No | AM9: =IF(OR(AC9<>"Completed",AB9="Failed"),"Excluded","Included") -> Included | AN9: =IF(OR(D9="Invalid/Unrecognized",E9="Invalid/Unrecognized",G9="Invalid - Ship Before Order",X9="Negative - Invalid",X9="Above Allowed Range - Invalid",AG9="Mismatch",AH9="Mismatch",AK9="Conflicting Duplicate - Flagged for Review"),"Invalid",IF(OR(L9="Filled - Unknown",S9="Filled - Unknown",X9="Missing - Defaulted to 0",AL9="Yes",AC9="Cancelled",AC9="Returned"),"Warning","Clean")) -> Clean
A10: =raw_data!A10 -> ORD-2024-10009 | B10: =IFERROR(IF(MID(raw_data!B10,3,1)="/",DATE(VALUE(RIGHT(raw_data!B10,4)),VALUE(LEFT(raw_data!B10,2)),VALUE(MID(raw_data!B10,4,2))),IF(MID(raw_data!B10,3,1)="-",DATE(VALUE(RIGHT(raw_data!B10,4)),VALUE(MID(raw_data!B10,4,2)),VALUE(LEFT(raw_data!B10,2))),IF(MID(raw_data!B10,5,1)="-",DATE(VALUE(LEFT(raw_data!B10,4)),VALUE(MID(raw_data!B10,6,2)),VALUE(RIGHT(raw_data!B10,2))),DATE(VALUE(RIGHT(raw_data!B10,4)),MATCH(MID(raw_data!B10,4,3),{"Jan","Feb","Mar","Apr","May","Jun","Jul","Aug","Sep","Oct","Nov","Dec"},0),VALUE(LEFT(raw_data!B10,2)))))),"") -> 45601 | C10: =IFERROR(IF(MID(raw_data!C10,3,1)="/",DATE(VALUE(RIGHT(raw_data!C10,4)),VALUE(LEFT(raw_data!C10,2)),VALUE(MID(raw_data!C10,4,2))),IF(MID(raw_data!C10,3,1)="-",DATE(VALUE(RIGHT(raw_data!C10,4)),VALUE(MID(raw_data!C10,4,2)),VALUE(LEFT(raw_data!C10,2))),IF(MID(raw_data!C10,5,1)="-",DATE(VALUE(LEFT(raw_data!C10,4)),VALUE(MID(raw_data!C10,6,2)),VALUE(RIGHT(raw_data!C10,2))),DATE(VALUE(RIGHT(raw_data!C10,4)),MATCH(MID(raw_data!C10,4,3),{"Jan","Feb","Mar","Apr","May","Jun","Jul","Aug","Sep","Oct","Nov","Dec"},0),VALUE(LEFT(raw_data!C10,2)))))),"") -> 45606 | D10: =IF(TRIM(raw_data!B10)="","Missing",IF(B10="","Invalid/Unrecognized","Valid")) -> Valid | E10: =IF(TRIM(raw_data!C10)="","Missing",IF(C10="","Invalid/Unrecognized","Valid")) -> Valid | F10: =IF(OR(B10="",C10=""),"",C10-B10) -> 5 | G10: =IF(F10="","N/A",IF(F10<0,"Invalid - Ship Before Order","OK")) -> OK | H10: =raw_data!D10 -> CUST-2598 | I10: =PROPER(TRIM(raw_data!E10)) -> Aditi Sen | J10: =PROPER(TRIM(raw_data!F10)) -> Corporate | K10: =IF(TRIM(raw_data!G10)="","Unknown",PROPER(TRIM(raw_data!G10))) -> South | L10: =IF(TRIM(raw_data!G10)="","Filled - Unknown","OK") -> OK | M10: =PROPER(TRIM(raw_data!H10)) -> Telangana | N10: =PROPER(TRIM(raw_data!I10)) -> Hyderabad | O10: =PROPER(TRIM(raw_data!J10)) -> Office Supplies | P10: =PROPER(TRIM(raw_data!K10)) -> Labels | Q10: =TRIM(raw_data!L10) -> Classic Labels 815 | R10: =IF(TRIM(raw_data!M10)="","Unknown",PROPER(TRIM(raw_data!M10))) -> First Class | S10: =IF(TRIM(raw_data!M10)="","Filled - Unknown","OK") -> OK | T10: =raw_data!N10 -> 8 | U10: =raw_data!O10 -> 3134.2 | V10: =raw_data!P10 -> 0 | W10: =IF(raw_data!P10="",0,IF(ISTEXT(raw_data!P10),IF(RIGHT(raw_data!P10,1)="%",VALUE(LEFT(raw_data!P10,LEN(raw_data!P10)-1))/100,VALUE(raw_data!P10)),raw_data!P10)) -> 0 | X10: =IF(raw_data!P10="","Missing - Defaulted to 0",IF(W10<0,"Negative - Invalid",IF(W10>0.3,"Above Allowed Range - Invalid","Valid"))) -> Valid | Y10: =raw_data!Q10 -> 25073.6 | Z10: =raw_data!R10 -> 17347.23 | AA10: =raw_data!S10 -> 7726.37 | AB10: =PROPER(TRIM(raw_data!T10)) -> Paid | AC10: =PROPER(TRIM(raw_data!U10)) -> Completed | AD10: =T10*U10*(1-W10) -> 25073.6 | AE10: =AD10-Z10 -> 7726.37 | AF10: =IF(AD10=0,0,AE10/AD10) -> 0.30814761 | AG10: =IF(ABS(Y10-AD10)>1,"Mismatch","OK") -> OK | AH10: =IF(ABS(AA10-AE10)>1,"Mismatch","OK") -> OK | AI10: =IF(B10="","",MONTH(B10)) -> 11 | AJ10: =IF(B10="","",YEAR(B10)) -> 2024 | AK10: =IF(COUNTIF(raw_data!$A$2:$A$913,A10)>1,"Conflicting Duplicate - Flagged for Review","Unique") -> Unique | AL10: =IF(AB10="Refunded","Yes","No") -> No | AM10: =IF(OR(AC10<>"Completed",AB10="Failed"),"Excluded","Included") -> Included | AN10: =IF(OR(D10="Invalid/Unrecognized",E10="Invalid/Unrecognized",G10="Invalid - Ship Before Order",X10="Negative - Invalid",X10="Above Allowed Range - Invalid",AG10="Mismatch",AH10="Mismatch",AK10="Conflicting Duplicate - Flagged for Review"),"Invalid",IF(OR(L10="Filled - Unknown",S10="Filled - Unknown",X10="Missing - Defaulted to 0",AL10="Yes",AC10="Cancelled",AC10="Returned"),"Warning","Clean")) -> Clean
A11: =raw_data!A11 -> ORD-2025-10010 | B11: =IFERROR(IF(MID(raw_data!B11,3,1)="/",DATE(VALUE(RIGHT(raw_data!B11,4)),VALUE(LEFT(raw_data!B11,2)),VALUE(MID(raw_data!B11,4,2))),IF(MID(raw_data!B11,3,1)="-",DATE(VALUE(RIGHT(raw_data!B11,4)),VALUE(MID(raw_data!B11,4,2)),VALUE(LEFT(raw_data!B11,2))),IF(MID(raw_data!B11,5,1)="-",DATE(VALUE(LEFT(raw_data!B11,4)),VALUE(MID(raw_data!B11,6,2)),VALUE(RIGHT(raw_data!B11,2))),DATE(VALUE(RIGHT(raw_data!B11,4)),MATCH(MID(raw_data!B11,4,3),{"Jan","Feb","Mar","Apr","May","Jun","Jul","Aug","Sep","Oct","Nov","Dec"},0),VALUE(LEFT(raw_data!B11,2)))))),"") -> 45907 | C11: =IFERROR(IF(MID(raw_data!C11,3,1)="/",DATE(VALUE(RIGHT(raw_data!C11,4)),VALUE(LEFT(raw_data!C11,2)),VALUE(MID(raw_data!C11,4,2))),IF(MID(raw_data!C11,3,1)="-",DATE(VALUE(RIGHT(raw_data!C11,4)),VALUE(MID(raw_data!C11,4,2)),VALUE(LEFT(raw_data!C11,2))),IF(MID(raw_data!C11,5,1)="-",DATE(VALUE(LEFT(raw_data!C11,4)),VALUE(MID(raw_data!C11,6,2)),VALUE(RIGHT(raw_data!C11,2))),DATE(VALUE(RIGHT(raw_data!C11,4)),MATCH(MID(raw_data!C11,4,3),{"Jan","Feb","Mar","Apr","May","Jun","Jul","Aug","Sep","Oct","Nov","Dec"},0),VALUE(LEFT(raw_data!C11,2)))))),"") -> 45912 | D11: =IF(TRIM(raw_data!B11)="","Missing",IF(B11="","Invalid/Unrecognized","Valid")) -> Valid | E11: =IF(TRIM(raw_data!C11)="","Missing",IF(C11="","Invalid/Unrecognized","Valid")) -> Valid | F11: =IF(OR(B11="",C11=""),"",C11-B11) -> 5 | G11: =IF(F11="","N/A",IF(F11<0,"Invalid - Ship Before Order","OK")) -> OK | H11: =raw_data!D11 -> CUST-2483 | I11: =PROPER(TRIM(raw_data!E11)) -> Mira Das | J11: =PROPER(TRIM(raw_data!F11)) -> Home Office | K11: =IF(TRIM(raw_data!G11)="","Unknown",PROPER(TRIM(raw_data!G11))) -> South | L11: =IF(TRIM(raw_data!G11)="","Filled - Unknown","OK") -> OK | M11: =PROPER(TRIM(raw_data!H11)) -> Telangana | N11: =PROPER(TRIM(raw_data!I11)) -> Hyderabad | O11: =PROPER(TRIM(raw_data!J11)) -> Office Supplies | P11: =PROPER(TRIM(raw_data!K11)) -> Paper | Q11: =TRIM(raw_data!L11) -> Pro Paper 622 | R11: =IF(TRIM(raw_data!M11)="","Unknown",PROPER(TRIM(raw_data!M11))) -> Second Class | S11: =IF(TRIM(raw_data!M11)="","Filled - Unknown","OK") -> OK | T11: =raw_data!N11 -> 9 | U11: =raw_data!O11 -> 852.04 | V11: =raw_data!P11 -> 0.2 | W11: =IF(raw_data!P11="",0,IF(ISTEXT(raw_data!P11),IF(RIGHT(raw_data!P11,1)="%",VALUE(LEFT(raw_data!P11,LEN(raw_data!P11)-1))/100,VALUE(raw_data!P11)),raw_data!P11)) -> 0.2 | X11: =IF(raw_data!P11="","Missing - Defaulted to 0",IF(W11<0,"Negative - Invalid",IF(W11>0.3,"Above Allowed Range - Invalid","Valid"))) -> Valid | Y11: =raw_data!Q11 -> 6134.69 | Z11: =raw_data!R11 -> 3800.19 | AA11: =raw_data!S11 -> 2334.5 | AB11: =PROPER(TRIM(raw_data!T11)) -> Paid | AC11: =PROPER(TRIM(raw_data!U11)) -> Completed | AD11: =T11*U11*(1-W11) -> 6134.688 | AE11: =AD11-Z11 -> 2334.498 | AF11: =IF(AD11=0,0,AE11/AD11) -> 0.38054062 | AG11: =IF(ABS(Y11-AD11)>1,"Mismatch","OK") -> OK | AH11: =IF(ABS(AA11-AE11)>1,"Mismatch","OK") -> OK | AI11: =IF(B11="","",MONTH(B11)) -> 9 | AJ11: =IF(B11="","",YEAR(B11)) -> 2025 | AK11: =IF(COUNTIF(raw_data!$A$2:$A$913,A11)>1,"Conflicting Duplicate - Flagged for Review","Unique") -> Unique | AL11: =IF(AB11="Refunded","Yes","No") -> No | AM11: =IF(OR(AC11<>"Completed",AB11="Failed"),"Excluded","Included") -> Included | AN11: =IF(OR(D11="Invalid/Unrecognized",E11="Invalid/Unrecognized",G11="Invalid - Ship Before Order",X11="Negative - Invalid",X11="Above Allowed Range - Invalid",AG11="Mismatch",AH11="Mismatch",AK11="Conflicting Duplicate - Flagged for Review"),"Invalid",IF(OR(L11="Filled - Unknown",S11="Filled - Unknown",X11="Missing - Defaulted to 0",AL11="Yes",AC11="Cancelled",AC11="Returned"),"Warning","Clean")) -> Clean
A12: =raw_data!A12 -> ORD-2025-10011 | B12: =IFERROR(IF(MID(raw_data!B12,3,1)="/",DATE(VALUE(RIGHT(raw_data!B12,4)),VALUE(LEFT(raw_data!B12,2)),VALUE(MID(raw_data!B12,4,2))),IF(MID(raw_data!B12,3,1)="-",DATE(VALUE(RIGHT(raw_data!B12,4)),VALUE(MID(raw_data!B12,4,2)),VALUE(LEFT(raw_data!B12,2))),IF(MID(raw_data!B12,5,1)="-",DATE(VALUE(LEFT(raw_data!B12,4)),VALUE(MID(raw_data!B12,6,2)),VALUE(RIGHT(raw_data!B12,2))),DATE(VALUE(RIGHT(raw_data!B12,4)),MATCH(MID(raw_data!B12,4,3),{"Jan","Feb","Mar","Apr","May","Jun","Jul","Aug","Sep","Oct","Nov","Dec"},0),VALUE(LEFT(raw_data!B12,2)))))),"") -> 45797 | C12: =IFERROR(IF(MID(raw_data!C12,3,1)="/",DATE(VALUE(RIGHT(raw_data!C12,4)),VALUE(LEFT(raw_data!C12,2)),VALUE(MID(raw_data!C12,4,2))),IF(MID(raw_data!C12,3,1)="-",DATE(VALUE(RIGHT(raw_data!C12,4)),VALUE(MID(raw_data!C12,4,2)),VALUE(LEFT(raw_data!C12,2))),IF(MID(raw_data!C12,5,1)="-",DATE(VALUE(LEFT(raw_data!C12,4)),VALUE(MID(raw_data!C12,6,2)),VALUE(RIGHT(raw_data!C12,2))),DATE(VALUE(RIGHT(raw_data!C12,4)),MATCH(MID(raw_data!C12,4,3),{"Jan","Feb","Mar","Apr","May","Jun","Jul","Aug","Sep","Oct","Nov","Dec"},0),VALUE(LEFT(raw_data!C12,2)))))),"") -> 45797 | D12: =IF(TRIM(raw_data!B12)="","Missing",IF(B12="","Invalid/Unrecognized","Valid")) -> Valid | E12: =IF(TRIM(raw_data!C12)="","Missing",IF(C12="","Invalid/Unrecognized","Valid")) -> Valid | F12: =IF(OR(B12="",C12=""),"",C12-B12) -> 0 | G12: =IF(F12="","N/A",IF(F12<0,"Invalid - Ship Before Order","OK")) -> OK | H12: =raw_data!D12 -> CUST-8092 | I12: =PROPER(TRIM(raw_data!E12)) -> Ananya Rao | J12: =PROPER(TRIM(raw_data!F12)) -> Corporate | K12: =IF(TRIM(raw_data!G12)="","Unknown",PROPER(TRIM(raw_data!G12))) -> East | L12: =IF(TRIM(raw_data!G12)="","Filled - Unknown","OK") -> OK | M12: =PROPER(TRIM(raw_data!H12)) -> West Bengal | N12: =PROPER(TRIM(raw_data!I12)) -> Kolkata | O12: =PROPER(TRIM(raw_data!J12)) -> Office Supplies | P12: =PROPER(TRIM(raw_data!K12)) -> Labels | Q12: =TRIM(raw_data!L12) -> Prime Labels 644 | R12: =IF(TRIM(raw_data!M12)="","Unknown",PROPER(TRIM(raw_data!M12))) -> Second Class | S12: =IF(TRIM(raw_data!M12)="","Filled - Unknown","OK") -> OK | T12: =raw_data!N12 -> 3 | U12: =raw_data!O12 -> 3534.83 | V12: =raw_data!P12 -> 0.05 | W12: =IF(raw_data!P12="",0,IF(ISTEXT(raw_data!P12),IF(RIGHT(raw_data!P12,1)="%",VALUE(LEFT(raw_data!P12,LEN(raw_data!P12)-1))/100,VALUE(raw_data!P12)),raw_data!P12)) -> 0.05 | X12: =IF(raw_data!P12="","Missing - Defaulted to 0",IF(W12<0,"Negative - Invalid",IF(W12>0.3,"Above Allowed Range - Invalid","Valid"))) -> Valid | Y12: =raw_data!Q12 -> 10074.27 | Z12: =raw_data!R12 -> 6048.27 | AA12: =raw_data!S12 -> 4026 | AB12: =PROPER(TRIM(raw_data!T12)) -> Refunded | AC12: =PROPER(TRIM(raw_data!U12)) -> Returned | AD12: =T12*U12*(1-W12) -> 10074.265 | AE12: =AD12-Z12 -> 4025.9955 | AF12: =IF(AD12=0,0,AE12/AD12) -> 0.39963167 | AG12: =IF(ABS(Y12-AD12)>1,"Mismatch","OK") -> OK | AH12: =IF(ABS(AA12-AE12)>1,"Mismatch","OK") -> OK | AI12: =IF(B12="","",MONTH(B12)) -> 5 | AJ12: =IF(B12="","",YEAR(B12)) -> 2025 | AK12: =IF(COUNTIF(raw_data!$A$2:$A$913,A12)>1,"Conflicting Duplicate - Flagged for Review","Unique") -> Unique | AL12: =IF(AB12="Refunded","Yes","No") -> Yes | AM12: =IF(OR(AC12<>"Completed",AB12="Failed"),"Excluded","Included") -> Excluded | AN12: =IF(OR(D12="Invalid/Unrecognized",E12="Invalid/Unrecognized",G12="Invalid - Ship Before Order",X12="Negative - Invalid",X12="Above Allowed Range - Invalid",AG12="Mismatch",AH12="Mismatch",AK12="Conflicting Duplicate - Flagged for Review"),"Invalid",IF(OR(L12="Filled - Unknown",S12="Filled - Unknown",X12="Missing - Defaulted to 0",AL12="Yes",AC12="Cancelled",AC12="Returned"),"Warning","Clean")) -> Warning
A13: =raw_data!A13 -> ORD-2024-10012 | B13: =IFERROR(IF(MID(raw_data!B13,3,1)="/",DATE(VALUE(RIGHT(raw_data!B13,4)),VALUE(LEFT(raw_data!B13,2)),VALUE(MID(raw_data!B13,4,2))),IF(MID(raw_data!B13,3,1)="-",DATE(VALUE(RIGHT(raw_data!B13,4)),VALUE(MID(raw_data!B13,4,2)),VALUE(LEFT(raw_data!B13,2))),IF(MID(raw_data!B13,5,1)="-",DATE(VALUE(LEFT(raw_data!B13,4)),VALUE(MID(raw_data!B13,6,2)),VALUE(RIGHT(raw_data!B13,2))),DATE(VALUE(RIGHT(raw_data!B13,4)),MATCH(MID(raw_data!B13,4,3),{"Jan","Feb","Mar","Apr","May","Jun","Jul","Aug","Sep","Oct","Nov","Dec"},0),VALUE(LEFT(raw_data!B13,2)))))),"") -> 45495 | C13: =IFERROR(IF(MID(raw_data!C13,3,1)="/",DATE(VALUE(RIGHT(raw_data!C13,4)),VALUE(LEFT(raw_data!C13,2)),VALUE(MID(raw_data!C13,4,2))),IF(MID(raw_data!C13,3,1)="-",DATE(VALUE(RIGHT(raw_data!C13,4)),VALUE(MID(raw_data!C13,4,2)),VALUE(LEFT(raw_data!C13,2))),IF(MID(raw_data!C13,5,1)="-",DATE(VALUE(LEFT(raw_data!C13,4)),VALUE(MID(raw_data!C13,6,2)),VALUE(RIGHT(raw_data!C13,2))),DATE(VALUE(RIGHT(raw_data!C13,4)),MATCH(MID(raw_data!C13,4,3),{"Jan","Feb","Mar","Apr","May","Jun","Jul","Aug","Sep","Oct","Nov","Dec"},0),VALUE(LEFT(raw_data!C13,2)))))),"") -> 45496 | D13: =IF(TRIM(raw_data!B13)="","Missing",IF(B13="","Invalid/Unrecognized","Valid")) -> Valid | E13: =IF(TRIM(raw_data!C13)="","Missing",IF(C13="","Invalid/Unrecognized","Valid")) -> Valid | F13: =IF(OR(B13="",C13=""),"",C13-B13) -> 1 | G13: =IF(F13="","N/A",IF(F13<0,"Invalid - Ship Before Order","OK")) -> OK | H13: =raw_data!D13 -> CUST-6528 | I13: =PROPER(TRIM(raw_data!E13)) -> Vikram Iyer | J13: =PROPER(TRIM(raw_data!F13)) -> Small Business | K13: =IF(TRIM(raw_data!G13)="","Unknown",PROPER(TRIM(raw_data!G13))) -> East | L13: =IF(TRIM(raw_data!G13)="","Filled - Unknown","OK") -> OK | M13: =PROPER(TRIM(raw_data!H13)) -> Odisha | N13: =PROPER(TRIM(raw_data!I13)) -> Bhubaneswar | O13: =PROPER(TRIM(raw_data!J13)) -> Technology | P13: =PROPER(TRIM(raw_data!K13)) -> Accessories | Q13: =TRIM(raw_data!L13) -> Smart Accessories 603 | R13: =IF(TRIM(raw_data!M13)="","Unknown",PROPER(TRIM(raw_data!M13))) -> Same Day | S13: =IF(TRIM(raw_data!M13)="","Filled - Unknown","OK") -> OK | T13: =raw_data!N13 -> 6 | U13: =raw_data!O13 -> 2005.95 | V13: =raw_data!P13 -> 0.2 | W13: =IF(raw_data!P13="",0,IF(ISTEXT(raw_data!P13),IF(RIGHT(raw_data!P13,1)="%",VALUE(LEFT(raw_data!P13,LEN(raw_data!P13)-1))/100,VALUE(raw_data!P13)),raw_data!P13)) -> 0.2 | X13: =IF(raw_data!P13="","Missing - Defaulted to 0",IF(W13<0,"Negative - Invalid",IF(W13>0.3,"Above Allowed Range - Invalid","Valid"))) -> Valid | Y13: =raw_data!Q13 -> 9628.56 | Z13: =raw_data!R13 -> 8038.59 | AA13: =raw_data!S13 -> 1589.97 | AB13: =PROPER(TRIM(raw_data!T13)) -> Paid | AC13: =PROPER(TRIM(raw_data!U13)) -> Completed | AD13: =T13*U13*(1-W13) -> 9628.56 | AE13: =AD13-Z13 -> 1589.97 | AF13: =IF(AD13=0,0,AE13/AD13) -> 0.16513061 | AG13: =IF(ABS(Y13-AD13)>1,"Mismatch","OK") -> OK | AH13: =IF(ABS(AA13-AE13)>1,"Mismatch","OK") -> OK | AI13: =IF(B13="","",MONTH(B13)) -> 7 | AJ13: =IF(B13="","",YEAR(B13)) -> 2024 | AK13: =IF(COUNTIF(raw_data!$A$2:$A$913,A13)>1,"Conflicting Duplicate - Flagged for Review","Unique") -> Unique | AL13: =IF(AB13="Refunded","Yes","No") -> No | AM13: =IF(OR(AC13<>"Completed",AB13="Failed"),"Excluded","Included") -> Included | AN13: =IF(OR(D13="Invalid/Unrecognized",E13="Invalid/Unrecognized",G13="Invalid - Ship Before Order",X13="Negative - Invalid",X13="Above Allowed Range - Invalid",AG13="Mismatch",AH13="Mismatch",AK13="Conflicting Duplicate - Flagged for Review"),"Invalid",IF(OR(L13="Filled - Unknown",S13="Filled - Unknown",X13="Missing - Defaulted to 0",AL13="Yes",AC13="Cancelled",AC13="Returned"),"Warning","Clean")) -> Clean
... A913: =raw_data!A913 -> ORD-2025-10336 | B913: =IFERROR(IF(MID(raw_data!B913,3,1)="/",DATE(VALUE(RIGHT(raw_data!B913,4)),VALUE(LEFT(raw_data!B913,2)),VALUE(MID(raw_data!B913,4,2))),IF(MID(raw_data!B913,3,1)="-",DATE(VALUE(RIGHT(raw_data!B913,4)),VALUE(MID(raw_data!B913,4,2)),VALUE(LEFT(raw_data!B913,2))),IF(MID(raw_data!B913,5,1)="-",DATE(VALUE(LEFT(raw_data!B913,4)),VALUE(MID(raw_data!B913,6,2)),VALUE(RIGHT(raw_data!B913,2))),DATE(VALUE(RIGHT(raw_data!B913,4)),MATCH(MID(raw_data!B913,4,3),{"Jan","Feb","Mar","Apr","May","Jun","Jul","Aug","Sep","Oct","Nov","Dec"},0),VALUE(LEFT(raw_data!B913,2)))))),"") -> 45824 | C913: =IFERROR(IF(MID(raw_data!C913,3,1)="/",DATE(VALUE(RIGHT(raw_data!C913,4)),VALUE(LEFT(raw_data!C913,2)),VALUE(MID(raw_data!C913,4,2))),IF(MID(raw_data!C913,3,1)="-",DATE(VALUE(RIGHT(raw_data!C913,4)),VALUE(MID(raw_data!C913,4,2)),VALUE(LEFT(raw_data!C913,2))),IF(MID(raw_data!C913,5,1)="-",DATE(VALUE(LEFT(raw_data!C913,4)),VALUE(MID(raw_data!C913,6,2)),VALUE(RIGHT(raw_data!C913,2))),DATE(VALUE(RIGHT(raw_data!C913,4)),MATCH(MID(raw_data!C913,4,3),{"Jan","Feb","Mar","Apr","May","Jun","Jul","Aug","Sep","Oct","Nov","Dec"},0),VALUE(LEFT(raw_data!C913,2)))))),"") -> 45826 | D913: =IF(TRIM(raw_data!B913)="","Missing",IF(B913="","Invalid/Unrecognized","Valid")) -> Valid | E913: =IF(TRIM(raw_data!C913)="","Missing",IF(C913="","Invalid/Unrecognized","Valid")) -> Valid | F913: =IF(OR(B913="",C913=""),"",C913-B913) -> 2 | G913: =IF(F913="","N/A",IF(F913<0,"Invalid - Ship Before Order","OK")) -> OK | H913: =raw_data!D913 -> CUST-3621 | I913: =PROPER(TRIM(raw_data!E913)) -> Rahul Verma | J913: =PROPER(TRIM(raw_data!F913)) -> Home Office | K913: =IF(TRIM(raw_data!G913)="","Unknown",PROPER(TRIM(raw_data!G913))) -> West | L913: =IF(TRIM(raw_data!G913)="","Filled - Unknown","OK") -> OK | M913: =PROPER(TRIM(raw_data!H913)) -> Madhya Pradesh | N913: =PROPER(TRIM(raw_data!I913)) -> Indore | O913: =PROPER(TRIM(raw_data!J913)) -> Office Supplies | P913: =PROPER(TRIM(raw_data!K913)) -> Paper | Q913: =TRIM(raw_data!L913) -> Prime Paper 559 | R913: =IF(TRIM(raw_data!M913)="","Unknown",PROPER(TRIM(raw_data!M913))) -> First Class | S913: =IF(TRIM(raw_data!M913)="","Filled - Unknown","OK") -> OK | T913: =raw_data!N913 -> 3 | U913: =raw_data!O913 -> 4289.37 | V913: =raw_data!P913 -> 0.1 | W913: =IF(raw_data!P913="",0,IF(ISTEXT(raw_data!P913),IF(RIGHT(raw_data!P913,1)="%",VALUE(LEFT(raw_data!P913,LEN(raw_data!P913)-1))/100,VALUE(raw_data!P913)),raw_data!P913)) -> 0.1 | X913: =IF(raw_data!P913="","Missing - Defaulted to 0",IF(W913<0,"Negative - Invalid",IF(W913>0.3,"Above Allowed Range - Invalid","Valid"))) -> Valid | Y913: =raw_data!Q913 -> 11778.71 | Z913: =raw_data!R913 -> 6829.43 | AA913: =raw_data!S913 -> 4751.87 | AB913: =PROPER(TRIM(raw_data!T913)) -> Paid | AC913: =PROPER(TRIM(raw_data!U913)) -> Returned | AD913: =T913*U913*(1-W913) -> 11581.299 | AE913: =AD913-Z913 -> 4751.869 | AF913: =IF(AD913=0,0,AE913/AD913) -> 0.41030536 | AG913: =IF(ABS(Y913-AD913)>1,"Mismatch","OK") -> Mismatch | AH913: =IF(ABS(AA913-AE913)>1,"Mismatch","OK") -> OK | AI913: =IF(B913="","",MONTH(B913)) -> 6 | AJ913: =IF(B913="","",YEAR(B913)) -> 2025 | AK913: =IF(COUNTIF(raw_data!$A$2:$A$913,A913)>1,"Conflicting Duplicate - Flagged for Review","Unique") -> Conflicting Duplicate - Flagged for Review | AL913: =IF(AB913="Refunded","Yes","No") -> No | AM913: =IF(OR(AC913<>"Completed",AB913="Failed"),"Excluded","Included") -> Excluded | AN913: =IF(OR(D913="Invalid/Unrecognized",E913="Invalid/Unrecognized",G913="Invalid - Ship Before Order",X913="Negative - Invalid",X913="Above Allowed Range - Invalid",AG913="Mismatch",AH913="Mismatch",AK913="Conflicting Duplicate - Flagged for Review"),"Invalid",IF(OR(L913="Filled - Unknown",S913="Filled - Unknown",X913="Missing - Defaulted to 0",AL913="Yes",AC913="Cancelled",AC913="Returned"),"Warning","Clean")) -> Invalid

Sheet raw_data
A1: order_id | B1: order_date | C1: ship_date | D1: customer_id | E1: customer_name | F1: segment | G1: region | H1: state | I1: city | J1: category | K1: sub_category | L1: product_name | M1: ship_mode | N1: quantity | O1: unit_price | P1: discount | Q1: sales | R1: cost | S1: profit | T1: payment_status | U1: order_status
A2: ORD-2024-10001 | B2: 21 Jul 2024 | C2: 07/27/2024 | D2: CUST-4655 | E2: Karan Malhotra | F2: Consumer | G2: North | H2: Rajasthan | I2: Jaipur | J2: Office Supplies | K2: Paper | L2: Pro Paper 122 | M2: Second Class | N2: 8 | O2: 2976.45 | P2: 0.2 | Q2: 19049.28 | R2: 15841.89 | S2: 3207.39 | T2: Paid | U2: Completed
A3: ORD-2024-10002 | B3: 08/31/2024 | C3: 05 Sep 2024 | D3: CUST-2054 | E3: Mira Das | F3: Small Business | G3: East | H3: Odisha | I3: Bhubaneswar | J3: Furniture | K3: Tables | L3: Pro Tables 258 | M3: Same Day | N3: 3 | O3: 2437.5 | P3: 0 | Q3: 7312.5 | R3: 4904.73 | S3: 2407.77 | T3: Paid | U3: Completed
A4: ORD-2024-10003 | B4: 06/08/2024 | C4: 15 Jun 2024 | D4: CUST-6843 | E4: Isha Nair | F4: Consumer | G4: East | H4: Odisha | I4: Bhubaneswar | J4: Office Supplies | K4: Art | L4: Elite Art 525 | M4: First Class | N4: 4 | O4: 1065.43 | P4: 0.55 | Q4: 4261.72 | R4: 2465.69 | S4: 1796.03 | T4: Paid | U4: Completed
A5: ORD-2024-10004 | B5: 28-11-2024 | C5: 11/29/2024 | D5: CUST-3722 | E5: Arjun Bose | F5: Small Business | G5: South | H5: Telangana | I5: Hyderabad | J5: Furniture | K5: Furnishings | L5: Smart Furnishings 294 | M5: Standard Class | N5: 6 | O5: 1848.43 | P5: 0.25 | Q5: 8317.93 | R5: 6796.77 | S5: 1521.16 | T5: Paid | U5: Completed
A6: ORD-2025-10005 | B6: 29 Aug 2025 | C6: 2025-09-01 | D6: CUST-8130 | E6: Ananya Rao | F6: Small Business | G6: West | H6: Maharashtra | I6: Mumbai | J6: Furniture | K6: Chairs | L6: Elite Chairs 543 | M6: First Class | N6: 7 | O6: 2973.76 | P6: 0 | Q6: 20816.32 | R6: 17705.37 | S6: 3110.95 | T6: Paid | U6: Cancelled
A7: ORD-2024-10006 | B7: 2024-05-24 | C7: 28-05-2024 | D7: CUST-6056 | E7: Vikram Iyer | F7: Small Business | G7: West | H7: Madhya Pradesh | I7: Indore | J7: Technology | K7: Accessories | L7: Pro Accessories 821 | M7: Same Day | N7: 3 | O7: 1053.11 | P7: 0.2 | Q7: 2527.46 | R7: 1533.58 | S7: 993.88 | T7: Paid | U7: Completed
A8: ORD-2025-10007 | B8: 04/10/2025 | C8: 04/16/2025 | D8: CUST-3656 | E8: Neha Gupta | F8: Consumer | G8: East | H8: Odisha | I8: Bhubaneswar | J8: Technology | K8: Copiers | L8: Eco Copiers 790 | M8: Standard Class | N8: 4 | O8: 1719.87 | P8: 0.15 | Q8: 5847.56 | R8: 4727.25 | S8: 1120.31 | T8: Paid | U8: Completed
A9: ORD-2025-10008 | B9: 2025-02-23 | C9: 26-02-2025 | D9: CUST-4683 | E9: Isha Nair | F9: Small Business | G9: South | H9: Andhra Pradesh | I9: Vijayawada | J9: Office Supplies | K9: Art | L9: Eco Art 848 | M9: First Class | N9: 1 | O9: 2980.71 | P9: 0 | Q9: 2980.71 | R9: 2357.22 | S9: 623.49 | T9: Paid | U9: Completed
A10: ORD-2024-10009 | B10: 11/05/2024 | C10: 11/10/2024 | D10: CUST-2598 | E10: Aditi Sen | F10: Corporate | G10: South | H10: Telangana | I10: Hyderabad | J10: Office Supplies | K10: Labels | L10: Classic Labels 815 | M10: First Class | N10: 8 | O10: 3134.2 | P10: 0 | Q10: 25073.6 | R10: 17347.23 | S10: 7726.37 | T10: Paid | U10: Completed
A11: ORD-2025-10010 | B11: 07-09-2025 | C11: 09/12/2025 | D11: CUST-2483 | E11: Mira Das | F11: Home Office | G11: South | H11: Telangana | I11: Hyderabad | J11: Office Supplies | K11: Paper | L11: Pro Paper 622 | M11: Second Class | N11: 9 | O11: 852.04 | P11: 0.2 | Q11: 6134.69 | R11: 3800.19 | S11: 2334.5 | T11: Paid | U11: Completed
A12: ORD-2025-10011 | B12: 20 May 2025 | C12: 05/20/2025 | D12: CUST-8092 | E12: Ananya Rao | F12: Corporate | G12: East | H12: West Bengal | I12: Kolkata | J12: Office Supplies | K12: Labels | L12: Prime Labels 644 | M12: Second Class | N12: 3 | O12: 3534.83 | P12: 0.05 | Q12: 10074.27 | R12: 6048.27 | S12: 4026 | T12: Refunded | U12: Returned
A13: ORD-2024-10012 | B13: 2024-07-22 | C13: 23-07-2024 | D13: CUST-6528 | E13: Vikram Iyer | F13: Small Business | G13: East | H13: Odisha | I13: Bhubaneswar | J13: Technology | K13: Accessories | L13: Smart Accessories 603 | M13: Same Day | N13: 6 | O13: 2005.95 | P13: 0.2 | Q13: 9628.56 | R13: 8038.59 | S13: 1589.97 | T13: Paid | U13: Completed
... A33: ORD-2025-10032 | B33: 15-06-2025 | C33: 19-06-2025 | D33: CUST-7867 | E33: Karan Malhotra | F33: Small Business | G33: West | H33: Madhya Pradesh | I33: Indore | J33: Office Supplies | K33: Paper | L33: Pro Paper 959 | M33: Second Class | N33: 9 | O33: 3092.55 | P33: 0 | Q33: 27832.95 | R33: 17769.75 | S33: 10063.2 | T33: Failed | U33: Returned
A34: ORD-2024-10033 | B34: 22-11-2024 | C34: 2024-11-26 | D34: CUST-6509 | E34: Aarav Sharma | F34: Corporate | G34: South | H34: Andhra Pradesh | I34: Vijayawada | J34: Technology | K34: Phones | L34: Basic Phones 242 | M34: Second Class | N34: 3 | O34: 4001.25 | Q34: 9002.81 | R34: 7529.92 | S34: 1472.89 | T34: Paid | U34: Completed
A35: ORD-2024-10034 | B35: 07/22/2024 | C35: 27-07-2024 | D35: CUST-6660 | E35: Priya Menon | F35: Home Office | G35: West | H35: Goa | I35: Panaji | J35: Furniture | K35: Tables | L35: Max Tables 836 | M35: Same Day | N35: 7 | O35: 492.41 | P35: 0.25 | Q35: 2585.15 | R35: 2070.73 | S35: 514.42 | T35: Paid | U35: Completed
A36: ORD-2025-10035 | B36: 2025-01-31 | C36: 2025-02-05 | D36: CUST-2392 | E36: Priya Menon | F36: Home Office | G36: East | H36: West Bengal | I36: Kolkata | J36: Furniture | K36: Chairs | L36: Elite Chairs 862 | N36: 2 | O36: 4159.69 | P36: 0.2 | Q36: 6655.5 | R36: 4340.21 | S36: 2607.32 | T36: Paid | U36: Completed
A37: ORD-2024-10036 | B37: 29-05-2024 | C37: 29 May 2024 | D37: CUST-1611 | E37: Sneha Kapoor | F37: Small Business | G37: West | H37: Gujarat | I37: Ahmedabad | J37: Furniture | K37: Bookcases | L37: Prime Bookcases 414 | M37: Second Class | N37: 8 | O37: 2507.12 | P37: 0.05 | Q37: 19054.11 | R37: 15313.83 | S37: 3740.28 | T37: Pending | U37: Returned
A38: ORD-2024-10037 | B38: 2024-10-25 | C38: 28 Oct 2024 | D38: CUST-8296 | E38: Rohan Mehta | F38: Corporate | G38: West | H38: Maharashtra | I38: Mumbai | J38: Furniture | K38: Bookcases | L38: Eco Bookcases 220 | M38: Second Class | N38: 3 | O38: 3126.47 | P38: 0 | Q38: 9379.41 | R38: 6670.85 | S38: 2708.56 | T38: Paid | U38: Returned
A39: ORD-2025-10038 | B39: 29-07-2025 | C39: 29-07-2025 | D39: CUST-4646 | E39: Diya Patel | F39: Consumer | G39: West | H39: Maharashtra | I39: Mumbai | J39: Technology | K39: Copiers | L39: Pro Copiers 830 | M39: STANDARD CLASS | N39: 4 | O39: 1327.54 | P39: 0.2 | Q39: 4248.13 | R39: 3321.09 | S39: 927.04 | T39: Paid | U39: Completed
A40: ORD-2024-10039 | B40: 2024-06-17 | C40: 22-06-2024 | D40: CUST-8235 | E40: Aarav Sharma | F40: Corporate | G40: West | H40: Gujarat | I40: Ahmedabad | J40: Technology | K40: Phones | L40: Prime Phones 507 | M40: First Class | N40: 7 | O40: 2210.68 | P40: 0.1 | Q40: 13927.28 | R40: 10504.87 | S40: 3422.41 | T40: Paid | U40: Completed
A41: ORD-2024-10040 | B41: 12/11/2024 | C41: 2024-12-11 | D41: CUST-5830 | E41: Mira Das | F41: Small Business | G41: West | H41: Madhya Pradesh | I41: Indore | J41: Technology | K41: Copiers | L41: Classic Copiers 590 | M41: First Class | N41: 4 | O41: 1370.92 | P41: 0.1 | Q41: 4935.31 | R41: 3374.77 | S41: 1560.54 | T41: Pending | U41: Returned
A42: ORD-2024-10041 | B42: 10-10-2024 | C42: 16 Oct 2024 | D42: CUST-7178 | E42: Isha Nair | F42: Home Office | G42: West | H42: Rajasthan | I42: Udaipur | J42: Technology | K42: Copiers | L42: Eco Copiers 865 | M42: Standard Class | N42: 7 | O42: 2509.27 | P42: 0.2 | Q42: 14051.91 | R42: 11990.37 | S42: 2061.54 | T42: Paid | U42: Completed
A43: ORD-2024-10042 | B43: 03/12/2024 | C43: 17-03-2024 | D43: CUST-3829 | E43: Aarav Sharma | F43: Small Business | G43: East | H43: Odisha | I43: Bhubaneswar | J43: Furniture | K43: Bookcases | L43: Classic Bookcases 835 | M43: Same Day | N43: 8 | O43: 855.81 | P43: 0 | Q43: 6846.48 | R43: 4239.89 | S43: 2606.59 | T43: Pending | U43: Cancelled
A44: ORD-2025-10043 | B44: 2025-10-10 | C44: 15 Oct 2025 | D44: CUST-6708 | E44: Arjun Bose | F44: Corporate | G44: East | H44: Jharkhand | I44: Ranchi | J44: Technology | K44: Phones | L44: Eco Phones 702 | M44: Standard Class | N44: 8 | O44: 979.87 | P44: 0.05 | Q44: 7447.01 | R44: 4496.22 | S44: 2950.79 | T44: Paid | U44: Completed
A45: ORD-2024-10044 | B45: 07/08/2024 | C45: 07/14/2024 | D45: CUST-7119 | E45: Priya Menon | F45: Small Business | G45: East | H45: Odisha | I45: Bhubaneswar | J45: Furniture | K45: Furnishings | L45: Smart Furnishings 956 | M45: Same Day | N45: 3 | O45: 1010.23 | P45: 0 | Q45: 3030.69 | R45: 1721.08 | S45: 1309.61 | T45: Paid | U45: Completed
A46: ORD-2024-10045 | B46: 06/22/2024 | C46: 25-06-2024 | D46: CUST-3373 | E46: Rohan Mehta | F46: Small Business | G46: North | H46: Haryana | I46: Gurugram | J46: Furniture | K46: Chairs | L46: Max Chairs 393 | M46: Standard Class | N46: 9 | O46: 3329.77 | P46: 0.1 | Q46: 26971.14 | R46: 17376.2 | S46: 9594.94 | T46: Paid | U46: Completed
A47: ORD-2024-10046 | B47: 18 Jan 2024 | C47: 24-01-2024 | D47: CUST-8896 | E47: Isha Nair | F47: Home Office | G47: East | H47: Bihar | I47: Patna | J47: Office Supplies | K47: Art | L47: Prime Art 221 | M47: Second Class | N47: 8 | O47: 3927.82 | P47: 0.05 | Q47: 29851.43 | R47: 17487.48 | S47: 12363.95 | T47: Pending | U47: Returned
A48: ORD-2024-10047 | B48: 19-07-2024 | C48: 19-07-2024 | D48: CUST-8517 | E48: Ananya Rao | F48: Small Business | G48: South | H48: Kerala | I48: Kochi | J48: Furniture | K48: Bookcases | L48: Elite Bookcases 671 | M48: Standard Class | N48: 9 | O48: 2386.79 | P48: 0.25 | Q48: 16110.83 | R48: 10680.03 | S48: 5430.8 | T48: Refunded | U48: Returned
... A59: ORD-2024-10058 | B59: 2024-02-07 | C59: 15 Feb 2024 | D59: CUST-9941 | E59: Priya Menon | F59: Consumer | G59: West | H59: Goa | I59: Panaji | J59: Furniture | K59: Chairs | L59: Max Chairs 813 | M59: Same Day | N59: 5 | O59: 255.87 | P59: 0 | Q59: 1279.35 | R59: 1091.54 | S59: 187.81 | T59: Paid | U59: Completed
A60: ORD-2024-10059 | B60: 2024-09-01 | C60: 2024-09-07 | D60: CUST-3983 | E60: Isha Nair | F60: Home Office | G60: North | H60: Rajasthan | I60: Jaipur | J60: Office Supplies | K60: Storage | L60: Basic Storage 872 | N60: 9 | O60: 1389.48 | P60: 0.1 | Q60: 11254.79 | R60: 6578.06 | S60: 4676.73 | T60: Pending | U60: Returned
A61: ORD-2024-10060 | B61: 20-07-2024 | C61: 25 Jul 2024 | D61: CUST-2418 | E61: Priya Menon | F61: Corporate | G61: East | H61: Assam | I61: Guwahati | J61: Office Supplies | K61: Labels | L61: Smart Labels 655 | M61: Same Day | N61: 5 | O61: 4133.85 | P61: 0.2 | Q61: 16535.4 | R61: 12990.21 | S61: 3545.19 | T61: Paid | U61: Cancelled
A62: ORD-2024-10061 | B62: 07/13/2024 | C62: 2024-07-19 | D62: CUST-2892 | E62: Ananya Rao | F62: Corporate | G62: East | H62: Assam | I62: Guwahati | J62: Office Supplies | K62: Labels | L62: Eco Labels 210 | M62: Same Day | N62: 3 | O62: 275.76 | P62: 0.2 | Q62: 661.82 | R62: 481.47 | S62: 180.35 | T62: Refunded | U62: Cancelled
A63: ORD-2024-10062 | B63: 16 Apr 2024 | C63: 04/16/2024 | D63: CUST-7008 | E63: Vikram Iyer | F63: Home Office | G63: East | H63: Bihar | I63: Patna | J63: Furniture | K63: Bookcases | L63: Classic Bookcases 296 | M63: Standard Class | N63: 1 | O63: 949.59 | P63: 0 | Q63: 949.59 | R63: 751.25 | S63: 198.34 | T63: Paid | U63: Completed
A64: ORD-2024-10063 | B64: 30 Oct 2024 | C64: 02-11-2024 | D64: CUST-4900 | E64: Sneha Kapoor | F64: Home Office | G64: North | H64: Rajasthan | I64: Jaipur | J64: Technology | K64: Phones | L64: Basic Phones 230 | M64: Standard Class | N64: 9 | O64: 3042.29 | P64: 0.2 | Q64: 21904.49 | R64: 13570.55 | S64: 8333.94 | T64: Paid | U64: Completed
A65: ORD-2024-10064 | B65: 2024-01-25 | C65: 01-02-2024 | D65: CUST-5382 | E65: Sneha Kapoor | F65: Home Office | G65: North | H65: Haryana | I65: Gurugram | J65: Office Supplies | K65: Binders | L65: Pro Binders 690 | M65: Same Day | N65: 2 | O65: 2832.77 | P65: 0.15 | Q65: 4815.71 | R65: 3027.75 | S65: 1917.47 | T65: Paid | U65: Completed
